Workbook
Name Slicer_Gender: #N/A

Sheet README

Sheet Mortality_Table_Male
A1: Iss. Age | B1: 1 | C1: 2 | D1: 3 | E1: 4 | F1: 5 | G1: 6 | H1: 7 | I1: 8 | J1: 9 | K1: 10 | L1: 11 | M1: 12 | N1: 13 | O1: 14 | P1: 15 | Q1: 16 | R1: 17 | S1: 18 | T1: 19 | U1: 20 | V1: 21 | W1: 22 | X1: 23 | Y1: 24 | Z1: 25 | AA1: Ult. | AB1: Att. Age
A2: 0 | B2: 0.00028 | C2: 0.00016 | D2: 0.00014 | E2: 0.00012 | F2: 0.00011 | G2: 0.0001 | H2: 0.0001 | I2: 0.0001 | J2: 9e-05 | K2: 9e-05 | L2: 9e-05 | M2: 0.0001 | N2: 0.00012 | O2: 0.00016 | P2: 0.00023 | Q2: 0.00035 | R2: 0.0005 | S2: 0.00069 | T2: 0.00083 | U2: 0.00086 | V2: 0.0009 | W2: 0.00093 | X2: 0.00096 | Y2: 0.00099 | Z2: 0.00102 | AA2: 0.00105 | AB2: 25
A3: 1 | B3: 0.00016 | C3: 0.00014 | D3: 0.00012 | E3: 0.00011 | F3: 0.0001 | G3: 0.0001 | H3: 0.0001 | I3: 9e-05 | J3: 9e-05 | K3: 9e-05 | L3: 0.0001 | M3: 0.00012 | N3: 0.00016 | O3: 0.00023 | P3: 0.00035 | Q3: 0.0005 | R3: 0.00069 | S3: 0.00083 | T3: 0.00086 | U3: 0.0009 | V3: 0.00093 | W3: 0.00096 | X3: 0.00099 | Y3: 0.00102 | Z3: 0.00105 | AA3: 0.00105 | AB3: 26
A4: 2 | B4: 0.00014 | C4: 0.00012 | D4: 0.00011 | E4: 0.0001 | F4: 0.0001 | G4: 0.0001 | H4: 9e-05 | I4: 9e-05 | J4: 9e-05 | K4: 0.0001 | L4: 0.00012 | M4: 0.00016 | N4: 0.00023 | O4: 0.00035 | P4: 0.0005 | Q4: 0.00069 | R4: 0.00083 | S4: 0.00086 | T4: 0.0009 | U4: 0.00093 | V4: 0.00096 | W4: 0.00099 | X4: 0.00102 | Y4: 0.00105 | Z4: 0.00105 | AA4: 0.00103 | AB4: 27
A5: 3 | B5: 0.00012 | C5: 0.00011 | D5: 0.0001 | E5: 0.0001 | F5: 0.0001 | G5: 9e-05 | H5: 9e-05 | I5: 9e-05 | J5: 0.0001 | K5: 0.00012 | L5: 0.00016 | M5: 0.00023 | N5: 0.00035 | O5: 0.0005 | P5: 0.00069 | Q5: 0.00083 | R5: 0.00086 | S5: 0.0009 | T5: 0.00093 | U5: 0.00096 | V5: 0.00099 | W5: 0.00102 | X5: 0.00105 | Y5: 0.00105 | Z5: 0.00103 | AA5: 0.00101 | AB5: 28
A6: 4 | B6: 0.00011 | C6: 0.0001 | D6: 0.0001 | E6: 0.0001 | F6: 9e-05 | G6: 9e-05 | H6: 9e-05 | I6: 0.0001 | J6: 0.00012 | K6: 0.00016 | L6: 0.00023 | M6: 0.00035 | N6: 0.0005 | O6: 0.00069 | P6: 0.00083 | Q6: 0.00086 | R6: 0.0009 | S6: 0.00093 | T6: 0.00096 | U6: 0.00099 | V6: 0.00102 | W6: 0.00105 | X6: 0.00105 | Y6: 0.00103 | Z6: 0.00101 | AA6: 0.001 | AB6: 29
A7: 5 | B7: 0.0001 | C7: 0.0001 | D7: 0.0001 | E7: 9e-05 | F7: 9e-05 | G7: 9e-05 | H7: 0.0001 | I7: 0.00012 | J7: 0.00016 | K7: 0.00023 | L7: 0.00035 | M7: 0.0005 | N7: 0.00069 | O7: 0.00083 | P7: 0.00086 | Q7: 0.0009 | R7: 0.00093 | S7: 0.00096 | T7: 0.00099 | U7: 0.00102 | V7: 0.00105 | W7: 0.00105 | X7: 0.00103 | Y7: 0.00101 | Z7: 0.001 | AA7: 0.001 | AB7: 30
A8: 6 | B8: 0.0001 | C8: 0.0001 | D8: 9e-05 | E8: 9e-05 | F8: 9e-05 | G8: 0.0001 | H8: 0.00012 | I8: 0.00016 | J8: 0.00023 | K8: 0.00035 | L8: 0.0005 | M8: 0.00069 | N8: 0.00083 | O8: 0.00086 | P8: 0.0009 | Q8: 0.00093 | R8: 0.00096 | S8: 0.00099 | T8: 0.00102 | U8: 0.00105 | V8: 0.00105 | W8: 0.00103 | X8: 0.00101 | Y8: 0.001 | Z8: 0.001 | AA8: 0.00104 | AB8: 31
A9: 7 | B9: 0.0001 | C9: 9e-05 | D9: 9e-05 | E9: 9e-05 | F9: 0.0001 | G9: 0.00012 | H9: 0.00016 | I9: 0.00023 | J9: 0.00035 | K9: 0.0005 | L9: 0.00069 | M9: 0.00083 | N9: 0.00086 | O9: 0.0009 | P9: 0.00093 | Q9: 0.00096 | R9: 0.00099 | S9: 0.00102 | T9: 0.00105 | U9: 0.00105 | V9: 0.00103 | W9: 0.00101 | X9: 0.001 | Y9: 0.001 | Z9: 0.00104 | AA9: 0.00111 | AB9: 32
A10: 8 | B10: 9e-05 | C10: 9e-05 | D10: 9e-05 | E10: 0.0001 | F10: 0.00012 | G10: 0.00016 | H10: 0.00023 | I10: 0.00035 | J10: 0.0005 | K10: 0.00069 | L10: 0.00083 | M10: 0.00086 | N10: 0.0009 | O10: 0.00093 | P10: 0.00096 | Q10: 0.00099 | R10: 0.00102 | S10: 0.00105 | T10: 0.00105 | U10: 0.00103 | V10: 0.00101 | W10: 0.001 | X10: 0.001 | Y10: 0.00104 | Z10: 0.00111 | AA10: 0.00119 | AB10: 33
A11: 9 | B11: 9e-05 | C11: 9e-05 | D11: 0.0001 | E11: 0.00012 | F11: 0.00016 | G11: 0.00023 | H11: 0.00035 | I11: 0.0005 | J11: 0.00069 | K11: 0.00083 | L11: 0.00086 | M11: 0.0009 | N11: 0.00093 | O11: 0.00096 | P11: 0.00099 | Q11: 0.00102 | R11: 0.00105 | S11: 0.00105 | T11: 0.00103 | U11: 0.00101 | V11: 0.001 | W11: 0.001 | X11: 0.00104 | Y11: 0.00111 | Z11: 0.00119 | AA11: 0.00128 | AB11: 34
A12: 10 | B12: 9e-05 | C12: 0.0001 | D12: 0.00012 | E12: 0.00016 | F12: 0.00023 | G12: 0.00035 | H12: 0.0005 | I12: 0.00069 | J12: 0.00083 | K12: 0.00086 | L12: 0.0009 | M12: 0.00093 | N12: 0.00096 | O12: 0.00099 | P12: 0.00102 | Q12: 0.00105 | R12: 0.00105 | S12: 0.00103 | T12: 0.00101 | U12: 0.001 | V12: 0.001 | W12: 0.00104 | X12: 0.00111 | Y12: 0.00119 | Z12: 0.00128 | AA12: 0.00137 | AB12: 35
A13: 11 | B13: 0.0001 | C13: 0.00012 | D13: 0.00016 | E13: 0.00023 | F13: 0.00035 | G13: 0.0005 | H13: 0.00069 | I13: 0.00083 | J13: 0.00086 | K13: 0.0009 | L13: 0.00093 | M13: 0.00096 | N13: 0.00099 | O13: 0.00102 | P13: 0.00105 | Q13: 0.00105 | R13: 0.00103 | S13: 0.00101 | T13: 0.001 | U13: 0.001 | V13: 0.00104 | W13: 0.00111 | X13: 0.00119 | Y13: 0.00128 | Z13: 0.00137 | AA13: 0.0015 | AB13: 36
... A97: 95 | B97: 0.13477 | C97: 0.2632 | D97: 0.28319 | E97: 0.30497 | F97: 0.3281 | G97: 0.35209 | H97: 0.37447 | I97: 0.3968 | J97: 0.41866 | K97: 0.43965 | L97: 0.45936 | M97: 0.47743 | N97: 0.50332 | O97: 0.53061 | P97: 0.55939 | Q97: 0.58972 | R97: 0.6217 | S97: 0.65542 | T97: 0.69096 | U97: 0.72843 | V97: 0.76794 | W97: 0.80958 | X97: 0.85348 | Y97: 0.89977 | Z97: 0.94856 | AA97: 1 | AB97: 120
A101: To divide by | B101: 1000

Sheet Mortality_Table_Female
A1: Iss. Age | B1: 1 | C1: 2 | D1: 3 | E1: 4 | F1: 5 | G1: 6 | H1: 7 | I1: 8 | J1: 9 | K1: 10 | L1: 11 | M1: 12 | N1: 13 | O1: 14 | P1: 15 | Q1: 16 | R1: 17 | S1: 18 | T1: 19 | U1: 20 | V1: 21 | W1: 22 | X1: 23 | Y1: 24 | Z1: 25 | AA1: Ult. | AB1: Att. Age
A2: 0 | B2: 0.0003 | C2: 0.00017 | D2: 0.00011 | E2: 8e-05 | F2: 8e-05 | G2: 8e-05 | H2: 9e-05 | I2: 9e-05 | J2: 8e-05 | K2: 8e-05 | L2: 9e-05 | M2: 9e-05 | N2: 9e-05 | O2: 8e-05 | P2: 0.00011 | Q2: 0.00019 | R2: 0.00027 | S2: 0.00032 | T2: 0.00033 | U2: 0.00033 | V2: 0.00033 | W2: 0.00033 | X2: 0.00033 | Y2: 0.00035 | Z2: 0.00039 | AA2: 0.00041 | AB2: 25
A3: 1 | B3: 0.00017 | C3: 0.00011 | D3: 8e-05 | E3: 8e-05 | F3: 8e-05 | G3: 9e-05 | H3: 9e-05 | I3: 8e-05 | J3: 8e-05 | K3: 9e-05 | L3: 9e-05 | M3: 9e-05 | N3: 8e-05 | O3: 0.00011 | P3: 0.00019 | Q3: 0.00027 | R3: 0.00032 | S3: 0.00033 | T3: 0.00033 | U3: 0.00033 | V3: 0.00033 | W3: 0.00033 | X3: 0.00035 | Y3: 0.00039 | Z3: 0.00041 | AA3: 0.00041 | AB3: 26
A4: 2 | B4: 0.00011 | C4: 8e-05 | D4: 8e-05 | E4: 8e-05 | F4: 9e-05 | G4: 9e-05 | H4: 8e-05 | I4: 8e-05 | J4: 9e-05 | K4: 9e-05 | L4: 9e-05 | M4: 8e-05 | N4: 0.00011 | O4: 0.00019 | P4: 0.00027 | Q4: 0.00032 | R4: 0.00033 | S4: 0.00033 | T4: 0.00033 | U4: 0.00033 | V4: 0.00033 | W4: 0.00035 | X4: 0.00039 | Y4: 0.00041 | Z4: 0.00041 | AA4: 0.00041 | AB4: 27
A5: 3 | B5: 8e-05 | C5: 8e-05 | D5: 8e-05 | E5: 9e-05 | F5: 9e-05 | G5: 8e-05 | H5: 8e-05 | I5: 9e-05 | J5: 9e-05 | K5: 9e-05 | L5: 8e-05 | M5: 0.00011 | N5: 0.00019 | O5: 0.00027 | P5: 0.00032 | Q5: 0.00033 | R5: 0.00033 | S5: 0.00033 | T5: 0.00033 | U5: 0.00033 | V5: 0.00035 | W5: 0.00039 | X5: 0.00041 | Y5: 0.00041 | Z5: 0.00041 | AA5: 0.00042 | AB5: 28
A6: 4 | B6: 8e-05 | C6: 8e-05 | D6: 9e-05 | E6: 9e-05 | F6: 8e-05 | G6: 8e-05 | H6: 9e-05 | I6: 9e-05 | J6: 9e-05 | K6: 8e-05 | L6: 0.00011 | M6: 0.00019 | N6: 0.00027 | O6: 0.00032 | P6: 0.00033 | Q6: 0.00033 | R6: 0.00033 | S6: 0.00033 | T6: 0.00033 | U6: 0.00035 | V6: 0.00039 | W6: 0.00041 | X6: 0.00041 | Y6: 0.00041 | Z6: 0.00042 | AA6: 0.00044 | AB6: 29
A7: 5 | B7: 8e-05 | C7: 9e-05 | D7: 9e-05 | E7: 8e-05 | F7: 8e-05 | G7: 9e-05 | H7: 9e-05 | I7: 9e-05 | J7: 8e-05 | K7: 0.00011 | L7: 0.00019 | M7: 0.00027 | N7: 0.00032 | O7: 0.00033 | P7: 0.00033 | Q7: 0.00033 | R7: 0.00033 | S7: 0.00033 | T7: 0.00035 | U7: 0.00039 | V7: 0.00041 | W7: 0.00041 | X7: 0.00041 | Y7: 0.00042 | Z7: 0.00044 | AA7: 0.00048 | AB7: 30
A8: 6 | B8: 9e-05 | C8: 9e-05 | D8: 8e-05 | E8: 8e-05 | F8: 9e-05 | G8: 9e-05 | H8: 9e-05 | I8: 8e-05 | J8: 0.00011 | K8: 0.00019 | L8: 0.00027 | M8: 0.00032 | N8: 0.00033 | O8: 0.00033 | P8: 0.00033 | Q8: 0.00033 | R8: 0.00033 | S8: 0.00035 | T8: 0.00039 | U8: 0.00041 | V8: 0.00041 | W8: 0.00041 | X8: 0.00042 | Y8: 0.00044 | Z8: 0.00048 | AA8: 0.00051 | AB8: 31
A9: 7 | B9: 9e-05 | C9: 8e-05 | D9: 8e-05 | E9: 9e-05 | F9: 9e-05 | G9: 9e-05 | H9: 8e-05 | I9: 0.00011 | J9: 0.00019 | K9: 0.00027 | L9: 0.00032 | M9: 0.00033 | N9: 0.00033 | O9: 0.00033 | P9: 0.00033 | Q9: 0.00033 | R9: 0.00035 | S9: 0.00039 | T9: 0.00041 | U9: 0.00041 | V9: 0.00041 | W9: 0.00042 | X9: 0.00044 | Y9: 0.00048 | Z9: 0.00051 | AA9: 0.00054 | AB9: 32
A10: 8 | B10: 8e-05 | C10: 8e-05 | D10: 9e-05 | E10: 9e-05 | F10: 9e-05 | G10: 8e-05 | H10: 0.00011 | I10: 0.00019 | J10: 0.00027 | K10: 0.00032 | L10: 0.00033 | M10: 0.00033 | N10: 0.00033 | O10: 0.00033 | P10: 0.00033 | Q10: 0.00035 | R10: 0.00039 | S10: 0.00041 | T10: 0.00041 | U10: 0.00041 | V10: 0.00042 | W10: 0.00044 | X10: 0.00048 | Y10: 0.00051 | Z10: 0.00054 | AA10: 0.00059 | AB10: 33
A11: 9 | B11: 8e-05 | C11: 9e-05 | D11: 9e-05 | E11: 9e-05 | F11: 8e-05 | G11: 0.00011 | H11: 0.00019 | I11: 0.00027 | J11: 0.00032 | K11: 0.00033 | L11: 0.00033 | M11: 0.00033 | N11: 0.00033 | O11: 0.00033 | P11: 0.00035 | Q11: 0.00039 | R11: 0.00041 | S11: 0.00041 | T11: 0.00041 | U11: 0.00042 | V11: 0.00044 | W11: 0.00048 | X11: 0.00051 | Y11: 0.00054 | Z11: 0.00059 | AA11: 0.00065 | AB11: 34
A12: 10 | B12: 9e-05 | C12: 9e-05 | D12: 9e-05 | E12: 8e-05 | F12: 0.00011 | G12: 0.00019 | H12: 0.00027 | I12: 0.00032 | J12: 0.00033 | K12: 0.00033 | L12: 0.00033 | M12: 0.00033 | N12: 0.00033 | O12: 0.00035 | P12: 0.00039 | Q12: 0.00041 | R12: 0.00041 | S12: 0.00041 | T12: 0.00042 | U12: 0.00044 | V12: 0.00048 | W12: 0.00051 | X12: 0.00054 | Y12: 0.00059 | Z12: 0.00065 | AA12: 0.00072 | AB12: 35
A13: 11 | B13: 9e-05 | C13: 9e-05 | D13: 8e-05 | E13: 0.00011 | F13: 0.00019 | G13: 0.00027 | H13: 0.00032 | I13: 0.00033 | J13: 0.00033 | K13: 0.00033 | L13: 0.00033 | M13: 0.00033 | N13: 0.00035 | O13: 0.00039 | P13: 0.00041 | Q13: 0.00041 | R13: 0.00041 | S13: 0.00042 | T13: 0.00044 | U13: 0.00048 | V13: 0.00051 | W13: 0.00054 | X13: 0.00059 | Y13: 0.00065 | Z13: 0.00072 | AA13: 0.00081 | AB13: 36
... A97: 95 | B97: 0.11028 | C97: 0.22427 | D97: 0.24847 | E97: 0.27475 | F97: 0.30273 | G97: 0.33199 | H97: 0.35742 | I97: 0.38258 | J97: 0.40703 | K97: 0.43037 | L97: 0.45219 | M97: 0.4721 | N97: 0.49811 | O97: 0.52554 | P97: 0.55448 | Q97: 0.58502 | R97: 0.61724 | S97: 0.65123 | T97: 0.6871 | U97: 0.72494 | V97: 0.76487 | W97: 0.80699 | X97: 0.85143 | Y97: 0.89833 | Z97: 0.9478 | AA97: 1 | AB97: 120
A100: To Divide By | B100: 1000

Sheet Lapse_Assumptions
A1: Policy Duration (Year) | B1: Lapse Rate | C1: Persistency Rate
A2: 1 | B2: 0.12 | C2: =1-B2 -> 0.88
A3: 2 | B3: 0.09 | C3: =1-B3 -> 0.91
A4: 3 | B4: 0.07 | C4: =1-B4 -> 0.93
A5: 4 | B5: 0.06 | C5: =1-B5 -> 0.94
A6: 5 | B6: 0.05 | C6: =1-B6 -> 0.95
A7: 6 | B7: 0.045 | C7: =1-B7 -> 0.955
A8: 7 | B8: 0.04 | C8: =1-B8 -> 0.96
A9: 8 | B9: 0.038 | C9: =1-B9 -> 0.962
A10: 9 | B10: 0.035 | C10: =1-B10 -> 0.965
A11: 10 | B11: 0.033 | C11: =1-B11 -> 0.967
A12: 11 | B12: 0.03 | C12: =1-B12 -> 0.97
A13: 12 | B13: 0.03 | C13: =1-B13 -> 0.97
... A31: 30 | B31: 0.03 | C31: =1-B31 -> 0.97

Sheet Expense_Assumptions
A1: Expense Category | B1: Basis | C1: Year 1 Rate | D1: Renewal Rate | E1: Notes
A2: Commissions (Agent) | B2: % of Premium | C2: 0.55 | D2: 0.05 | E2: Heaped first-year commission, level renewal
A3: Brokerage (Broker-sourced biz) | B3: % of Premium | C3: 0.5 | D3: 0.04 | E3: Similar structure, paid to broker not captive agent
A4: Underwriting/Acquisition Expense | B4: % of Face Amount | C4: 0.004 | D4: 0.0005 | E4: Medical exams, processing new business
A5: Maintenance Expense | B5: Per Policy ($) | C5: 65 | D5: 45 | E5: Annual servicing cost per in-force policy
A6: Premium Tax | B6: % of Premium | C6: 0.02 | D6: 0.02 | E6: State premium tax, flat across years

Sheet Premium Calculation
A1: PolicyID: | B1: POL1015
A2: Issue Age: | B2: 27
A3: Gender | B3: Female | D3: Net Annual Premium | G3: =D106 -> 988.13452
A4: Face Amount | B4: 250000
A5: Interest Rate | B5: 0.05
A8: Policy Year | B8: Age at Start of Year | C8: qx | D8: Survivial Probability to Year t | E8: Discount factor | F8: PV of Death Benefit | G8: PV of Premium Payment
A9: 1 | B9: =$B$2 +A9 - 1 -> 27 | C9: =IF(A9 < 25, INDEX(Mortality_Table_Female!$B$2:$AB$97, MATCH('Premium Calculation'!$B$2, Mortality_Table_Female!$A$2:$A$97, 0), MATCH(A9, Mortality_Table_Female!$B$1:$AB$1, 0)), INDEX(Mortality_Table_Female!$AA$2:$AA$97, MATCH('Premium Calculation'!B9, Mortality_Table_Female!$AB$2:$AB$97, 0))) -> 0.00012 | D9: 1 | E9: =1/(1+$B$5)^A9 -> 0.95238095 | F9: =D9*E9*C9*$B$4 -> 28.571429 | G9: =D9*(1/(1+$B$5)^(A9-1)) -> 1
A10: =A9+1 -> 2 | B10: =$B$2 +A10 - 1 -> 28 | C10: =IF(A10 < 25, INDEX(Mortality_Table_Female!$B$2:$AB$97, MATCH('Premium Calculation'!$B$2, Mortality_Table_Female!$A$2:$A$97, 0), MATCH(A10, Mortality_Table_Female!$B$1:$AB$1, 0)), INDEX(Mortality_Table_Female!$AA$2:$AA$97, MATCH('Premium Calculation'!B10, Mortality_Table_Female!$AB$2:$AB$97, 0))) -> 0.00017 | D10: =D9*(1-C9) -> 0.99988 | E10: =1/(1+$B$5)^A10 -> 0.90702948 | F10: =D10*E10*C10*$B$4 -> 38.544127 | G10: =D10*(1/(1+$B$5)^(A10-1)) -> 0.95226667
A11: =A10+1 -> 3 | B11: =$B$2 +A11 - 1 -> 29 | C11: =IF(A11 < 25, INDEX(Mortality_Table_Female!$B$2:$AB$97, MATCH('Premium Calculation'!$B$2, Mortality_Table_Female!$A$2:$A$97, 0), MATCH(A11, Mortality_Table_Female!$B$1:$AB$1, 0)), INDEX(Mortality_Table_Female!$AA$2:$AA$97, MATCH('Premium Calculation'!B11, Mortality_Table_Female!$AB$2:$AB$97, 0))) -> 0.0002 | D11: =D10*(1-C10) -> 0.99971002 | E11: =1/(1+$B$5)^A11 -> 0.8638376 | F11: =D11*E11*C11*$B$4 -> 43.179355 | G11: =D11*(1/(1+$B$5)^(A11-1)) -> 0.90676646
A12: =A11+1 -> 4 | B12: =$B$2 +A12 - 1 -> 30 | C12: =IF(A12 < 25, INDEX(Mortality_Table_Female!$B$2:$AB$97, MATCH('Premium Calculation'!$B$2, Mortality_Table_Female!$A$2:$A$97, 0), MATCH(A12, Mortality_Table_Female!$B$1:$AB$1, 0)), INDEX(Mortality_Table_Female!$AA$2:$AA$97, MATCH('Premium Calculation'!B12, Mortality_Table_Female!$AB$2:$AB$97, 0))) -> 0.00022 | D12: =D11*(1-C11) -> 0.99951008 | E12: =1/(1+$B$5)^A12 -> 0.82270247 | F12: =D12*E12*C12*$B$4 -> 45.226468 | G12: =D12*(1/(1+$B$5)^(A12-1)) -> 0.86341439
A13: =A12+1 -> 5 | B13: =$B$2 +A13 - 1 -> 31 | C13: =IF(A13 < 25, INDEX(Mortality_Table_Female!$B$2:$AB$97, MATCH('Premium Calculation'!$B$2, Mortality_Table_Female!$A$2:$A$97, 0), MATCH(A13, Mortality_Table_Female!$B$1:$AB$1, 0)), INDEX(Mortality_Table_Female!$AA$2:$AA$97, MATCH('Premium Calculation'!B13, Mortality_Table_Female!$AB$2:$AB$97, 0))) -> 0.00026 | D13: =D12*(1-C12) -> 0.99929019 | E13: =1/(1+$B$5)^A13 -> 0.78352617 | F13: =D13*E13*C13*$B$4 -> 50.893051 | G13: =D13*(1/(1+$B$5)^(A13-1)) -> 0.82211851
A14: =A13+1 -> 6 | B14: =$B$2 +A14 - 1 -> 32 | C14: =IF(A14 < 25, INDEX(Mortality_Table_Female!$B$2:$AB$97, MATCH('Premium Calculation'!$B$2, Mortality_Table_Female!$A$2:$A$97, 0), MATCH(A14, Mortality_Table_Female!$B$1:$AB$1, 0)), INDEX(Mortality_Table_Female!$AA$2:$AA$97, MATCH('Premium Calculation'!B14, Mortality_Table_Female!$AB$2:$AB$97, 0))) -> 0.00029 | D14: =D13*(1-C13) -> 0.99903037 | E14: =1/(1+$B$5)^A14 -> 0.7462154 | F14: =D14*E14*C14*$B$4 -> 54.048159 | G14: =D14*(1/(1+$B$5)^(A14-1)) -> 0.78276644
A15: =A14+1 -> 7 | B15: =$B$2 +A15 - 1 -> 33 | C15: =IF(A15 < 25, INDEX(Mortality_Table_Female!$B$2:$AB$97, MATCH('Premium Calculation'!$B$2, Mortality_Table_Female!$A$2:$A$97, 0), MATCH(A15, Mortality_Table_Female!$B$1:$AB$1, 0)), INDEX(Mortality_Table_Female!$AA$2:$AA$97, MATCH('Premium Calculation'!B15, Mortality_Table_Female!$AB$2:$AB$97, 0))) -> 0.00034 | D15: =D14*(1-C14) -> 0.99874065 | E15: =1/(1+$B$5)^A15 -> 0.71068133 | F15: =D15*E15*C15*$B$4 -> 60.331838 | G15: =D15*(1/(1+$B$5)^(A15-1)) -> 0.74527565
A16: =A15+1 -> 8 | B16: =$B$2 +A16 - 1 -> 34 | C16: =IF(A16 < 25, INDEX(Mortality_Table_Female!$B$2:$AB$97, MATCH('Premium Calculation'!$B$2, Mortality_Table_Female!$A$2:$A$97, 0), MATCH(A16, Mortality_Table_Female!$B$1:$AB$1, 0)), INDEX(Mortality_Table_Female!$AA$2:$AA$97, MATCH('Premium Calculation'!B16, Mortality_Table_Female!$AB$2:$AB$97, 0))) -> 0.0004 | D16: =D15*(1-C15) -> 0.99840108 | E16: =1/(1+$B$5)^A16 -> 0.67683936 | F16: =D16*E16*C16*$B$4 -> 67.575715 | G16: =D16*(1/(1+$B$5)^(A16-1)) -> 0.70954501
A17: =A16+1 -> 9 | B17: =$B$2 +A17 - 1 -> 35 | C17: =IF(A17 < 25, INDEX(Mortality_Table_Female!$B$2:$AB$97, MATCH('Premium Calculation'!$B$2, Mortality_Table_Female!$A$2:$A$97, 0), MATCH(A17, Mortality_Table_Female!$B$1:$AB$1, 0)), INDEX(Mortality_Table_Female!$AA$2:$AA$97, MATCH('Premium Calculation'!B17, Mortality_Table_Female!$AB$2:$AB$97, 0))) -> 0.00047 | D17: =D16*(1-C16) -> 0.99800172 | E17: =1/(1+$B$5)^A17 -> 0.64460892 | F17: =D17*E17*C17*$B$4 -> 75.590195 | G17: =D17*(1/(1+$B$5)^(A17-1)) -> 0.67548685
A18: =A17+1 -> 10 | B18: =$B$2 +A18 - 1 -> 36 | C18: =IF(A18 < 25, INDEX(Mortality_Table_Female!$B$2:$AB$97, MATCH('Premium Calculation'!$B$2, Mortality_Table_Female!$A$2:$A$97, 0), MATCH(A18, Mortality_Table_Female!$B$1:$AB$1, 0)), INDEX(Mortality_Table_Female!$AA$2:$AA$97, MATCH('Premium Calculation'!B18, Mortality_Table_Female!$AB$2:$AB$97, 0))) -> 0.00054 | D18: =D17*(1-C17) -> 0.99753266 | E18: =1/(1+$B$5)^A18 -> 0.61391325 | F18: =D18*E18*C18*$B$4 -> 82.6738 | G18: =D18*(1/(1+$B$5)^(A18-1)) -> 0.64301845
A19: =A18+1 -> 11 | B19: =$B$2 +A19 - 1 -> 37 | C19: =IF(A19 < 25, INDEX(Mortality_Table_Female!$B$2:$AB$97, MATCH('Premium Calculation'!$B$2, Mortality_Table_Female!$A$2:$A$97, 0), MATCH(A19, Mortality_Table_Female!$B$1:$AB$1, 0)), INDEX(Mortality_Table_Female!$AA$2:$AA$97, MATCH('Premium Calculation'!B19, Mortality_Table_Female!$AB$2:$AB$97, 0))) -> 0.00062 | D19: =D18*(1-C18) -> 0.99699399 | E19: =1/(1+$B$5)^A19 -> 0.58467929 | F19: =D19*E19*C19*$B$4 -> 90.352869 | G19: =D19*(1/(1+$B$5)^(A19-1)) -> 0.61206782
A20: =A19+1 -> 12 | B20: =$B$2 +A20 - 1 -> 38 | C20: =IF(A20 < 25, INDEX(Mortality_Table_Female!$B$2:$AB$97, MATCH('Premium Calculation'!$B$2, Mortality_Table_Female!$A$2:$A$97, 0), MATCH(A20, Mortality_Table_Female!$B$1:$AB$1, 0)), INDEX(Mortality_Table_Female!$AA$2:$AA$97, MATCH('Premium Calculation'!B20, Mortality_Table_Female!$AB$2:$AB$97, 0))) -> 0.00072 | D20: =D19*(1-C19) -> 0.99637585 | E20: =1/(1+$B$5)^A20 -> 0.55683742 | F20: =D20*E20*C20*$B$4 -> 99.867485 | G20: =D20*(1/(1+$B$5)^(A20-1)) -> 0.58256033
A21: =A20+1 -> 13 | B21: =$B$2 +A21 - 1 -> 39 | C21: =IF(A21 < 25, INDEX(Mortality_Table_Female!$B$2:$AB$97, MATCH('Premium Calculation'!$B$2, Mortality_Table_Female!$A$2:$A$97, 0), MATCH(A21, Mortality_Table_Female!$B$1:$AB$1, 0)), INDEX(Mortality_Table_Female!$AA$2:$AA$97, MATCH('Premium Calculation'!B21, Mortality_Table_Female!$AB$2:$AB$97, 0))) -> 0.00083 | D21: =D20*(1-C20) -> 0.99565846 | E21: =1/(1+$B$5)^A21 -> 0.53032135 | F21: =D21*E21*C21*$B$4 -> 109.56393 | G21: =D21*(1/(1+$B$5)^(A21-1)) -> 0.55441989
... A102: =A101+1 -> 94 | B102: =$B$2 +A102 - 1 -> 120 | C102: =IF(A102 < 25, INDEX(Mortality_Table_Female!$B$2:$AB$97, MATCH('Premium Calculation'!$B$2, Mortality_Table_Female!$A$2:$A$97, 0), MATCH(A102, Mortality_Table_Female!$B$1:$AB$1, 0)), INDEX(Mortality_Table_Female!$AA$2:$AA$97, MATCH('Premium Calculation'!B102, Mortality_Table_Female!$AB$2:$AB$97, 0))) -> 1 | D102: =D101*(1-C101) -> 1.4228388e-11 | E102: =1/(1+$B$5)^A102 -> 0.010190744 | F102: =D102*E102*C102*$B$4 -> 3.6249463e-08 | G102: =D102*(1/(1+$B$5)^(A102-1)) -> 1.5224775e-13
F103: =SUM(F9:F102) -> 19160.445 | G103: =SUM(G9:G102) -> 19.390523
A106: Net Premium | D106: ='Premium Calculation'!F103/'Premium Calculation'!G103 -> 988.13452

Sheet Reserve Calculation
A1: PolicyID: | B1: POL1015
A2: Issue Age: | B2: 27
A3: Gender | B3: Female
A4: Face Amount | B4: 250000
A5: Interest Rate | B5: 0.05
A6: Net Annual Premium | B6: ='Premium Calculation'!F103/'Premium Calculation'!G103 -> 988.13452
A8: Policy Year | B8: Age at Start of Year | C8: qx | D8: Reserve at Start of Year | E8: Premium Collected | F8: Fund After Premium | G8: Fund Accumulated with Interest | H8: Expected Death Benefit Payout | I8: Reserve at End of Year
A9: 1 | B9: =$B$2 + A9 - 1 -> 27 | C9: =IF(A9 < 25, INDEX(Mortality_Table_Female!$B$2:$AB$97, MATCH('Premium Calculation'!$B$2, Mortality_Table_Female!$A$2:$A$97, 0), MATCH(A9, Mortality_Table_Female!$B$1:$AB$1, 0)), INDEX(Mortality_Table_Female!$AA$2:$AA$97, MATCH('Premium Calculation'!B9, Mortality_Table_Female!$AB$2:$AB$97, 0))) -> 0.00012 | D9: 0 | E9: =$B$6 -> 988.13452 | F9: =E9+D9 -> 988.13452 | G9: =F9*(1+$B$5) -> 1037.5412 | H9: =C9*$B$4 -> 30 | I9: =(G9 - H9)/(1-C9) -> 1007.6622
A10: =A9+1 -> 2 | B10: =$B$2 + A10 - 1 -> 28 | C10: =IF(A10 < 25, INDEX(Mortality_Table_Female!$B$2:$AB$97, MATCH('Premium Calculation'!$B$2, Mortality_Table_Female!$A$2:$A$97, 0), MATCH(A10, Mortality_Table_Female!$B$1:$AB$1, 0)), INDEX(Mortality_Table_Female!$AA$2:$AA$97, MATCH('Premium Calculation'!B10, Mortality_Table_Female!$AB$2:$AB$97, 0))) -> 0.00017 | D10: =I9 -> 1007.6622 | E10: =$B$6 -> 988.13452 | F10: =E10+D10 -> 1995.7967 | G10: =F10*(1+$B$5) -> 2095.5865 | H10: =C10*$B$4 -> 42.5 | I10: =(G10 - H10)/(1-C10) -> 2053.4356
A11: =A10+1 -> 3 | B11: =$B$2 + A11 - 1 -> 29 | C11: =IF(A11 < 25, INDEX(Mortality_Table_Female!$B$2:$AB$97, MATCH('Premium Calculation'!$B$2, Mortality_Table_Female!$A$2:$A$97, 0), MATCH(A11, Mortality_Table_Female!$B$1:$AB$1, 0)), INDEX(Mortality_Table_Female!$AA$2:$AA$97, MATCH('Premium Calculation'!B11, Mortality_Table_Female!$AB$2:$AB$97, 0))) -> 0.0002 | D11: =I10 -> 2053.4356 | E11: =$B$6 -> 988.13452 | F11: =E11+D11 -> 3041.5701 | G11: =F11*(1+$B$5) -> 3193.6486 | H11: =C11*$B$4 -> 50 | I11: =(G11 - H11)/(1-C11) -> 3144.2775
A12: =A11+1 -> 4 | B12: =$B$2 + A12 - 1 -> 30 | C12: =IF(A12 < 25, INDEX(Mortality_Table_Female!$B$2:$AB$97, MATCH('Premium Calculation'!$B$2, Mortality_Table_Female!$A$2:$A$97, 0), MATCH(A12, Mortality_Table_Female!$B$1:$AB$1, 0)), INDEX(Mortality_Table_Female!$AA$2:$AA$97, MATCH('Premium Calculation'!B12, Mortality_Table_Female!$AB$2:$AB$97, 0))) -> 0.00022 | D12: =I11 -> 3144.2775 | E12: =$B$6 -> 988.13452 | F12: =E12+D12 -> 4132.412 | G12: =F12*(1+$B$5) -> 4339.0326 | H12: =C12*$B$4 -> 55 | I12: =(G12 - H12)/(1-C12) -> 4284.9753
A13: =A12+1 -> 5 | B13: =$B$2 + A13 - 1 -> 31 | C13: =IF(A13 < 25, INDEX(Mortality_Table_Female!$B$2:$AB$97, MATCH('Premium Calculation'!$B$2, Mortality_Table_Female!$A$2:$A$97, 0), MATCH(A13, Mortality_Table_Female!$B$1:$AB$1, 0)), INDEX(Mortality_Table_Female!$AA$2:$AA$97, MATCH('Premium Calculation'!B13, Mortality_Table_Female!$AB$2:$AB$97, 0))) -> 0.00026 | D13: =I12 -> 4284.9753 | E13: =$B$6 -> 988.13452 | F13: =E13+D13 -> 5273.1098 | G13: =F13*(1+$B$5) -> 5536.7653 | H13: =C13*$B$4 -> 65 | I13: =(G13 - H13)/(1-C13) -> 5473.1883
A14: =A13+1 -> 6 | B14: =$B$2 + A14 - 1 -> 32 | C14: =IF(A14 < 25, INDEX(Mortality_Table_Female!$B$2:$AB$97, MATCH('Premium Calculation'!$B$2, Mortality_Table_Female!$A$2:$A$97, 0), MATCH(A14, Mortality_Table_Female!$B$1:$AB$1, 0)), INDEX(Mortality_Table_Female!$AA$2:$AA$97, MATCH('Premium Calculation'!B14, Mortality_Table_Female!$AB$2:$AB$97, 0))) -> 0.00029 | D14: =I13 -> 5473.1883 | E14: =$B$6 -> 988.13452 | F14: =E14+D14 -> 6461.3229 | G14: =F14*(1+$B$5) -> 6784.389 | H14: =C14*$B$4 -> 72.5 | I14: =(G14 - H14)/(1-C14) -> 6713.836
A15: =A14+1 -> 7 | B15: =$B$2 + A15 - 1 -> 33 | C15: =IF(A15 < 25, INDEX(Mortality_Table_Female!$B$2:$AB$97, MATCH('Premium Calculation'!$B$2, Mortality_Table_Female!$A$2:$A$97, 0), MATCH(A15, Mortality_Table_Female!$B$1:$AB$1, 0)), INDEX(Mortality_Table_Female!$AA$2:$AA$97, MATCH('Premium Calculation'!B15, Mortality_Table_Female!$AB$2:$AB$97, 0))) -> 0.00034 | D15: =I14 -> 6713.836 | E15: =$B$6 -> 988.13452 | F15: =E15+D15 -> 7701.9705 | G15: =F15*(1+$B$5) -> 8087.0691 | H15: =C15*$B$4 -> 85 | I15: =(G15 - H15)/(1-C15) -> 8004.7907
A16: =A15+1 -> 8 | B16: =$B$2 + A16 - 1 -> 34 | C16: =IF(A16 < 25, INDEX(Mortality_Table_Female!$B$2:$AB$97, MATCH('Premium Calculation'!$B$2, Mortality_Table_Female!$A$2:$A$97, 0), MATCH(A16, Mortality_Table_Female!$B$1:$AB$1, 0)), INDEX(Mortality_Table_Female!$AA$2:$AA$97, MATCH('Premium Calculation'!B16, Mortality_Table_Female!$AB$2:$AB$97, 0))) -> 0.0004 | D16: =I15 -> 8004.7907 | E16: =$B$6 -> 988.13452 | F16: =E16+D16 -> 8992.9252 | G16: =F16*(1+$B$5) -> 9442.5715 | H16: =C16*$B$4 -> 100 | I16: =(G16 - H16)/(1-C16) -> 9346.31
A17: =A16+1 -> 9 | B17: =$B$2 + A17 - 1 -> 35 | C17: =IF(A17 < 25, INDEX(Mortality_Table_Female!$B$2:$AB$97, MATCH('Premium Calculation'!$B$2, Mortality_Table_Female!$A$2:$A$97, 0), MATCH(A17, Mortality_Table_Female!$B$1:$AB$1, 0)), INDEX(Mortality_Table_Female!$AA$2:$AA$97, MATCH('Premium Calculation'!B17, Mortality_Table_Female!$AB$2:$AB$97, 0))) -> 0.00047 | D17: =I16 -> 9346.31 | E17: =$B$6 -> 988.13452 | F17: =E17+D17 -> 10334.445 | G17: =F17*(1+$B$5) -> 10851.167 | H17: =C17*$B$4 -> 117.5 | I17: =(G17 - H17)/(1-C17) -> 10738.714
A18: =A17+1 -> 10 | B18: =$B$2 + A18 - 1 -> 36 | C18: =IF(A18 < 25, INDEX(Mortality_Table_Female!$B$2:$AB$97, MATCH('Premium Calculation'!$B$2, Mortality_Table_Female!$A$2:$A$97, 0), MATCH(A18, Mortality_Table_Female!$B$1:$AB$1, 0)), INDEX(Mortality_Table_Female!$AA$2:$AA$97, MATCH('Premium Calculation'!B18, Mortality_Table_Female!$AB$2:$AB$97, 0))) -> 0.00054 | D18: =I17 -> 10738.714 | E18: =$B$6 -> 988.13452 | F18: =E18+D18 -> 11726.848 | G18: =F18*(1+$B$5) -> 12313.191 | H18: =C18*$B$4 -> 135 | I18: =(G18 - H18)/(1-C18) -> 12184.771
A19: =A18+1 -> 11 | B19: =$B$2 + A19 - 1 -> 37 | C19: =IF(A19 < 25, INDEX(Mortality_Table_Female!$B$2:$AB$97, MATCH('Premium Calculation'!$B$2, Mortality_Table_Female!$A$2:$A$97, 0), MATCH(A19, Mortality_Table_Female!$B$1:$AB$1, 0)), INDEX(Mortality_Table_Female!$AA$2:$AA$97, MATCH('Premium Calculation'!B19, Mortality_Table_Female!$AB$2:$AB$97, 0))) -> 0.00062 | D19: =I18 -> 12184.771 | E19: =$B$6 -> 988.13452 | F19: =E19+D19 -> 13172.905 | G19: =F19*(1+$B$5) -> 13831.55 | H19: =C19*$B$4 -> 155 | I19: =(G19 - H19)/(1-C19) -> 13685.035
A20: =A19+1 -> 12 | B20: =$B$2 + A20 - 1 -> 38 | C20: =IF(A20 < 25, INDEX(Mortality_Table_Female!$B$2:$AB$97, MATCH('Premium Calculation'!$B$2, Mortality_Table_Female!$A$2:$A$97, 0), MATCH(A20, Mortality_Table_Female!$B$1:$AB$1, 0)), INDEX(Mortality_Table_Female!$AA$2:$AA$97, MATCH('Premium Calculation'!B20, Mortality_Table_Female!$AB$2:$AB$97, 0))) -> 0.00072 | D20: =I19 -> 13685.035 | E20: =$B$6 -> 988.13452 | F20: =E20+D20 -> 14673.17 | G20: =F20*(1+$B$5) -> 15406.828 | H20: =C20*$B$4 -> 180 | I20: =(G20 - H20)/(1-C20) -> 15237.799
A21: =A20+1 -> 13 | B21: =$B$2 + A21 - 1 -> 39 | C21: =IF(A21 < 25, INDEX(Mortality_Table_Female!$B$2:$AB$97, MATCH('Premium Calculation'!$B$2, Mortality_Table_Female!$A$2:$A$97, 0), MATCH(A21, Mortality_Table_Female!$B$1:$AB$1, 0)), INDEX(Mortality_Table_Female!$AA$2:$AA$97, MATCH('Premium Calculation'!B21, Mortality_Table_Female!$AB$2:$AB$97, 0))) -> 0.00083 | D21: =I20 -> 15237.799 | E21: =$B$6 -> 988.13452 | F21: =E21+D21 -> 16225.934 | G21: =F21*(1+$B$5) -> 17037.231 | H21: =C21*$B$4 -> 207.5 | I21: =(G21 - H21)/(1-C21) -> 16843.711
... A101: =A100+1 -> 93 | B101: =$B$2 + A101 - 1 -> 119 | C101: =IF(A101 < 25, INDEX(Mortality_Table_Female!$B$2:$AB$97, MATCH('Premium Calculation'!$B$2, Mortality_Table_Female!$A$2:$A$97, 0), MATCH(A101, Mortality_Table_Female!$B$1:$AB$1, 0)), INDEX(Mortality_Table_Female!$AA$2:$AA$97, MATCH('Premium Calculation'!B101, Mortality_Table_Female!$AB$2:$AB$97, 0))) -> 0.9478 | D101: =I100 -> 236476.12 | E101: =$B$6 -> 988.13452 | F101: =E101+D101 -> 237464.25 | G101: =F101*(1+$B$5) -> 249337.47 | H101: =C101*$B$4 -> 236950 | I101: =(G101 - H101)/(1-C101) -> 237307.79
A102: =A101+1 -> 94 | B102: =$B$2 + A102 - 1 -> 120 | C102: =IF(A102 < 25, INDEX(Mortality_Table_Female!$B$2:$AB$97, MATCH('Premium Calculation'!$B$2, Mortality_Table_Female!$A$2:$A$97, 0), MATCH(A102, Mortality_Table_Female!$B$1:$AB$1, 0)), INDEX(Mortality_Table_Female!$AA$2:$AA$97, MATCH('Premium Calculation'!B102, Mortality_Table_Female!$AB$2:$AB$97, 0))) -> 1 | D102: =I101 -> 237307.79 | E102: =$B$6 -> 988.13452 | F102: =E102+D102 -> 238295.93 | G102: =F102*(1+$B$5) -> 250210.73 | H102: =C102*$B$4 -> 250000 | I102: 0
A103: =A102+1 -> 95
A104: =A103+1 -> 96
A105: =A104+1 -> 97
A106: =A105+1 -> 98
A107: =A106+1 -> 99
A108: =A107+1 -> 100
A109: =A108+1 -> 101
A110: =A109+1 -> 102
A111: =A110+1 -> 103
A112: =A111+1 -> 104
A113: =A112+1 -> 105
A114: =A113+1 -> 106
... A134: =A133+1 -> 126
A135: =A134+1 -> 127 | B135: =$B$2 + A135 - 1 -> 153

Sheet Premium Calculation (2)
A1: PolicyID: | B1: POL1014
A2: Issue Age: | B2: 42
A3: Gender | B3: Male | D3: Net Annual Premium | G3: =D106 -> 921.82929
A4: Face Amount | B4: 100000
A5: Interest Rate | B5: 0.05
A8: Policy Year | B8: Age at Start of Year | C8: qx | D8: Survivial Probability to Year t | E8: Discount factor | F8: PV of Death Benefit | G8: PV of Premium Payment
A9: 1 | B9: =$B$2 +A9 - 1 -> 42 | C9: =IF(A9 < 25, INDEX(Mortality_Table_Male!$B$2:$AB$97, MATCH('Premium Calculation (2)'!$B$2, Mortality_Table_Male!$A$2:$A$97, 0), MATCH(A9, Mortality_Table_Male!$B$1:$AB$1, 0)), INDEX(Mortality_Table_Male!$AA$2:$AA$97, MATCH('Premium Calculation (2)'!B9, Mortality_Table_Male!$AB$2:$AB$97, 0))) -> 0.00039 | D9: 1 | E9: =1/(1+$B$5)^A9 -> 0.95238095 | F9: =D9*E9*C9*$B$4 -> 37.142857 | G9: =D9*(1/(1+$B$5)^(A9-1)) -> 1
A10: =A9+1 -> 2 | B10: =$B$2 +A10 - 1 -> 43 | C10: =IF(A10 < 25, INDEX(Mortality_Table_Male!$B$2:$AB$97, MATCH('Premium Calculation (2)'!$B$2, Mortality_Table_Male!$A$2:$A$97, 0), MATCH(A10, Mortality_Table_Male!$B$1:$AB$1, 0)), INDEX(Mortality_Table_Male!$AA$2:$AA$97, MATCH('Premium Calculation (2)'!B10, Mortality_Table_Male!$AB$2:$AB$97, 0))) -> 0.00067 | D10: =D9*(1-C9) -> 0.99961 | E10: =1/(1+$B$5)^A10 -> 0.90702948 | F10: =D10*E10*C10*$B$4 -> 60.747274 | G10: =D10*(1/(1+$B$5)^(A10-1)) -> 0.95200952
A11: =A10+1 -> 3 | B11: =$B$2 +A11 - 1 -> 44 | C11: =IF(A11 < 25, INDEX(Mortality_Table_Male!$B$2:$AB$97, MATCH('Premium Calculation (2)'!$B$2, Mortality_Table_Male!$A$2:$A$97, 0), MATCH(A11, Mortality_Table_Male!$B$1:$AB$1, 0)), INDEX(Mortality_Table_Male!$AA$2:$AA$97, MATCH('Premium Calculation (2)'!B11, Mortality_Table_Male!$AB$2:$AB$97, 0))) -> 0.00087 | D11: =D10*(1-C10) -> 0.99894026 | E11: =1/(1+$B$5)^A11 -> 0.8638376 | F11: =D11*E11*C11*$B$4 -> 75.074228 | G11: =D11*(1/(1+$B$5)^(A11-1)) -> 0.90606826
A12: =A11+1 -> 4 | B12: =$B$2 +A12 - 1 -> 45 | C12: =IF(A12 < 25, INDEX(Mortality_Table_Male!$B$2:$AB$97, MATCH('Premium Calculation (2)'!$B$2, Mortality_Table_Male!$A$2:$A$97, 0), MATCH(A12, Mortality_Table_Male!$B$1:$AB$1, 0)), INDEX(Mortality_Table_Male!$AA$2:$AA$97, MATCH('Premium Calculation (2)'!B12, Mortality_Table_Male!$AB$2:$AB$97, 0))) -> 0.00101 | D12: =D11*(1-C11) -> 0.99807118 | E12: =1/(1+$B$5)^A12 -> 0.82270247 | F12: =D12*E12*C12*$B$4 -> 82.932679 | G12: =D12*(1/(1+$B$5)^(A12-1)) -> 0.86217141
A13: =A12+1 -> 5 | B13: =$B$2 +A13 - 1 -> 46 | C13: =IF(A13 < 25, INDEX(Mortality_Table_Male!$B$2:$AB$97, MATCH('Premium Calculation (2)'!$B$2, Mortality_Table_Male!$A$2:$A$97, 0), MATCH(A13, Mortality_Table_Male!$B$1:$AB$1, 0)), INDEX(Mortality_Table_Male!$AA$2:$AA$97, MATCH('Premium Calculation (2)'!B13, Mortality_Table_Male!$AB$2:$AB$97, 0))) -> 0.00117 | D13: =D12*(1-C12) -> 0.99706313 | E13: =1/(1+$B$5)^A13 -> 0.78352617 | F13: =D13*E13*C13*$B$4 -> 91.403331 | G13: =D13*(1/(1+$B$5)^(A13-1)) -> 0.82028631
A14: =A13+1 -> 6 | B14: =$B$2 +A14 - 1 -> 47 | C14: =IF(A14 < 25, INDEX(Mortality_Table_Male!$B$2:$AB$97, MATCH('Premium Calculation (2)'!$B$2, Mortality_Table_Male!$A$2:$A$97, 0), MATCH(A14, Mortality_Table_Male!$B$1:$AB$1, 0)), INDEX(Mortality_Table_Male!$AA$2:$AA$97, MATCH('Premium Calculation (2)'!B14, Mortality_Table_Male!$AB$2:$AB$97, 0))) -> 0.00133 | D14: =D13*(1-C13) -> 0.99589657 | E14: =1/(1+$B$5)^A14 -> 0.7462154 | F14: =D14*E14*C14*$B$4 -> 98.839396 | G14: =D14*(1/(1+$B$5)^(A14-1)) -> 0.78031102
A15: =A14+1 -> 7 | B15: =$B$2 +A15 - 1 -> 48 | C15: =IF(A15 < 25, INDEX(Mortality_Table_Male!$B$2:$AB$97, MATCH('Premium Calculation (2)'!$B$2, Mortality_Table_Male!$A$2:$A$97, 0), MATCH(A15, Mortality_Table_Male!$B$1:$AB$1, 0)), INDEX(Mortality_Table_Male!$AA$2:$AA$97, MATCH('Premium Calculation (2)'!B15, Mortality_Table_Male!$AB$2:$AB$97, 0))) -> 0.00152 | D15: =D14*(1-C14) -> 0.99457203 | E15: =1/(1+$B$5)^A15 -> 0.71068133 | F15: =D15*E15*C15*$B$4 -> 107.43721 | G15: =D15*(1/(1+$B$5)^(A15-1)) -> 0.74216496
A16: =A15+1 -> 8 | B16: =$B$2 +A16 - 1 -> 49 | C16: =IF(A16 < 25, INDEX(Mortality_Table_Male!$B$2:$AB$97, MATCH('Premium Calculation (2)'!$B$2, Mortality_Table_Male!$A$2:$A$97, 0), MATCH(A16, Mortality_Table_Male!$B$1:$AB$1, 0)), INDEX(Mortality_Table_Male!$AA$2:$AA$97, MATCH('Premium Calculation (2)'!B16, Mortality_Table_Male!$AB$2:$AB$97, 0))) -> 0.00174 | D16: =D15*(1-C15) -> 0.99306028 | E16: =1/(1+$B$5)^A16 -> 0.67683936 | F16: =D16*E16*C16*$B$4 -> 116.95276 | G16: =D16*(1/(1+$B$5)^(A16-1)) -> 0.7057494
A17: =A16+1 -> 9 | B17: =$B$2 +A17 - 1 -> 50 | C17: =IF(A17 < 25, INDEX(Mortality_Table_Male!$B$2:$AB$97, MATCH('Premium Calculation (2)'!$B$2, Mortality_Table_Male!$A$2:$A$97, 0), MATCH(A17, Mortality_Table_Male!$B$1:$AB$1, 0)), INDEX(Mortality_Table_Male!$AA$2:$AA$97, MATCH('Premium Calculation (2)'!B17, Mortality_Table_Male!$AB$2:$AB$97, 0))) -> 0.002 | D17: =D16*(1-C16) -> 0.99133235 | E17: =1/(1+$B$5)^A17 -> 0.64460892 | F17: =D17*E17*C17*$B$4 -> 127.80433 | G17: =D17*(1/(1+$B$5)^(A17-1)) -> 0.67097276
A18: =A17+1 -> 10 | B18: =$B$2 +A18 - 1 -> 51 | C18: =IF(A18 < 25, INDEX(Mortality_Table_Male!$B$2:$AB$97, MATCH('Premium Calculation (2)'!$B$2, Mortality_Table_Male!$A$2:$A$97, 0), MATCH(A18, Mortality_Table_Male!$B$1:$AB$1, 0)), INDEX(Mortality_Table_Male!$AA$2:$AA$97, MATCH('Premium Calculation (2)'!B18, Mortality_Table_Male!$AB$2:$AB$97, 0))) -> 0.00228 | D18: =D17*(1-C17) -> 0.98934969 | E18: =1/(1+$B$5)^A18 -> 0.61391325 | F18: =D18*E18*C18*$B$4 -> 138.48147 | G18: =D18*(1/(1+$B$5)^(A18-1)) -> 0.63774363
A19: =A18+1 -> 11 | B19: =$B$2 +A19 - 1 -> 52 | C19: =IF(A19 < 25, INDEX(Mortality_Table_Male!$B$2:$AB$97, MATCH('Premium Calculation (2)'!$B$2, Mortality_Table_Male!$A$2:$A$97, 0), MATCH(A19, Mortality_Table_Male!$B$1:$AB$1, 0)), INDEX(Mortality_Table_Male!$AA$2:$AA$97, MATCH('Premium Calculation (2)'!B19, Mortality_Table_Male!$AB$2:$AB$97, 0))) -> 0.00254 | D19: =D18*(1-C18) -> 0.98709397 | E19: =1/(1+$B$5)^A19 -> 0.58467929 | F19: =D19*E19*C19*$B$4 -> 146.59188 | G19: =D19*(1/(1+$B$5)^(A19-1)) -> 0.60599007
A20: =A19+1 -> 12 | B20: =$B$2 +A20 - 1 -> 53 | C20: =IF(A20 < 25, INDEX(Mortality_Table_Male!$B$2:$AB$97, MATCH('Premium Calculation (2)'!$B$2, Mortality_Table_Male!$A$2:$A$97, 0), MATCH(A20, Mortality_Table_Male!$B$1:$AB$1, 0)), INDEX(Mortality_Table_Male!$AA$2:$AA$97, MATCH('Premium Calculation (2)'!B20, Mortality_Table_Male!$AB$2:$AB$97, 0))) -> 0.00283 | D20: =D19*(1-C19) -> 0.98458675 | E20: =1/(1+$B$5)^A20 -> 0.55683742 | F20: =D20*E20*C20*$B$4 -> 155.15609 | G20: =D20*(1/(1+$B$5)^(A20-1)) -> 0.57566748
A21: =A20+1 -> 13 | B21: =$B$2 +A21 - 1 -> 54 | C21: =IF(A21 < 25, INDEX(Mortality_Table_Male!$B$2:$AB$97, MATCH('Premium Calculation (2)'!$B$2, Mortality_Table_Male!$A$2:$A$97, 0), MATCH(A21, Mortality_Table_Male!$B$1:$AB$1, 0)), INDEX(Mortality_Table_Male!$AA$2:$AA$97, MATCH('Premium Calculation (2)'!B21, Mortality_Table_Male!$AB$2:$AB$97, 0))) -> 0.00321 | D21: =D20*(1-C20) -> 0.98180037 | E21: =1/(1+$B$5)^A21 -> 0.53032135 | F21: =D21*E21*C21*$B$4 -> 167.13497 | G21: =D21*(1/(1+$B$5)^(A21-1)) -> 0.54670318
... A87: =A86+1 -> 79 | B87: =$B$2 +A87 - 1 -> 120 | C87: =IF(A87 < 25, INDEX(Mortality_Table_Male!$B$2:$AB$97, MATCH('Premium Calculation (2)'!$B$2, Mortality_Table_Male!$A$2:$A$97, 0), MATCH(A87, Mortality_Table_Male!$B$1:$AB$1, 0)), INDEX(Mortality_Table_Male!$AA$2:$AA$97, MATCH('Premium Calculation (2)'!B87, Mortality_Table_Male!$AB$2:$AB$97, 0))) -> 1 | D87: =D86*(1-C86) -> 5.0578232e-12 | E87: =1/(1+$B$5)^A87 -> 0.021185825 | F87: =D87*E87*C87*$B$4 -> 1.0715415e-08 | G87: =D87*(1/(1+$B$5)^(A87-1)) -> 1.1251186e-13
F89: =SUM(F9:F87) -> 16218.727 | G89: =SUM(G9:G87) -> 17.594067
A106: Net Premium | D106: =F89/G89 -> 921.82929

Sheet Policy_Data
A1: Policy ID | B1: Issue Age | C1: Gender | D1: Policy Type | E1: Face Amount ($) | F1: Issue Date | G1: Current Duration (Yr) | H1: Attained Age | I1: qx (2-D lookup) | J1: Lapse Rate (lookup) | K1: Annual Premium (placeholder)
A2: POL1001 | B2: 25 | C2: Female | D2: Term-20 | E2: 100000 | F2: 38001 | G2: 22 | H2: =B2+G2 -> 47 | I2: =IF(C2= "Male", INDEX(Mortality_Table_Male!$B$2:$AB$97, MATCH(Policy_Data!$B2,Mortality_Table_Male!$A$2:$A$97, 0), MATCH(IF(Policy_Data!$G2 > 25, "Ult.", Policy_Data!$G2 ), Mortality_Table_Male!$B$1:$AB$1, 0)), INDEX(Mortality_Table_Female!$B$2:$AB$97, MATCH(Policy_Data!$B2,Mortality_Table_Female!$A$2:$A$97, 0), MATCH(IF(Policy_Data!$G2 > 25, "Ult.", Policy_Data!$G2 ), Mortality_Table_Female!$B$1:$AB$1, 0))) -> 0.00149 | J2: =INDEX(Lapse_Assumptions!$A$2:$C$31,MATCH(Policy_Data!$G2, Lapse_Assumptions!$A$2:$A$31, 0), 2) -> 0.03
A3: POL1002 | B3: 27 | C3: Male | D3: Term-20 | E3: 150000 | F3: 42019 | G3: 11 | H3: =B3+G3 -> 38 | I3: =IF(C3= "Male", INDEX(Mortality_Table_Male!$B$2:$AB$97, MATCH(Policy_Data!$B3,Mortality_Table_Male!$A$2:$A$97, 0), MATCH(IF(Policy_Data!$G3 > 25, "Ult.", Policy_Data!$G3 ), Mortality_Table_Male!$B$1:$AB$1, 0)), INDEX(Mortality_Table_Female!$B$2:$AB$97, MATCH(Policy_Data!$B3,Mortality_Table_Female!$A$2:$A$97, 0), MATCH(IF(Policy_Data!$G3 > 25, "Ult.", Policy_Data!$G3 ), Mortality_Table_Female!$B$1:$AB$1, 0))) -> 0.00081 | J3: =INDEX(Lapse_Assumptions!$A$2:$C$31,MATCH(Policy_Data!$G3, Lapse_Assumptions!$A$2:$A$31, 0), 2) -> 0.03
A4: POL1003 | B4: 57 | C4: Male | D4: Term-20 | E4: 500000 | F4: 44211 | G4: 5 | H4: =B4+G4 -> 62 | I4: =IF(C4= "Male", INDEX(Mortality_Table_Male!$B$2:$AB$97, MATCH(Policy_Data!$B4,Mortality_Table_Male!$A$2:$A$97, 0), MATCH(IF(Policy_Data!$G4 > 25, "Ult.", Policy_Data!$G4 ), Mortality_Table_Male!$B$1:$AB$1, 0)), INDEX(Mortality_Table_Female!$B$2:$AB$97, MATCH(Policy_Data!$B4,Mortality_Table_Female!$A$2:$A$97, 0), MATCH(IF(Policy_Data!$G4 > 25, "Ult.", Policy_Data!$G4 ), Mortality_Table_Female!$B$1:$AB$1, 0))) -> 0.00536 | J4: =INDEX(Lapse_Assumptions!$A$2:$C$31,MATCH(Policy_Data!$G4, Lapse_Assumptions!$A$2:$A$31, 0), 2) -> 0.05
A5: POL1004 | B5: 39 | C5: Female | D5: Whole Life | E5: 100000 | F5: 39462 | G5: 18 | H5: =B5+G5 -> 57 | I5: =IF(C5= "Male", INDEX(Mortality_Table_Male!$B$2:$AB$97, MATCH(Policy_Data!$B5,Mortality_Table_Male!$A$2:$A$97, 0), MATCH(IF(Policy_Data!$G5 > 25, "Ult.", Policy_Data!$G5 ), Mortality_Table_Male!$B$1:$AB$1, 0)), INDEX(Mortality_Table_Female!$B$2:$AB$97, MATCH(Policy_Data!$B5,Mortality_Table_Female!$A$2:$A$97, 0), MATCH(IF(Policy_Data!$G5 > 25, "Ult.", Policy_Data!$G5 ), Mortality_Table_Female!$B$1:$AB$1, 0))) -> 0.00318 | J5: =INDEX(Lapse_Assumptions!$A$2:$C$31,MATCH(Policy_Data!$G5, Lapse_Assumptions!$A$2:$A$31, 0), 2) -> 0.03
A6: POL1005 | B6: 52 | C6: Female | D6: Whole Life | E6: 150000 | F6: 42019 | G6: 11 | H6: =B6+G6 -> 63 | I6: =IF(C6= "Male", INDEX(Mortality_Table_Male!$B$2:$AB$97, MATCH(Policy_Data!$B6,Mortality_Table_Male!$A$2:$A$97, 0), MATCH(IF(Policy_Data!$G6 > 25, "Ult.", Policy_Data!$G6 ), Mortality_Table_Male!$B$1:$AB$1, 0)), INDEX(Mortality_Table_Female!$B$2:$AB$97, MATCH(Policy_Data!$B6,Mortality_Table_Female!$A$2:$A$97, 0), MATCH(IF(Policy_Data!$G6 > 25, "Ult.", Policy_Data!$G6 ), Mortality_Table_Female!$B$1:$AB$1, 0))) -> 0.00484 | J6: =INDEX(Lapse_Assumptions!$A$2:$C$31,MATCH(Policy_Data!$G6, Lapse_Assumptions!$A$2:$A$31, 0), 2) -> 0.03
A7: POL1006 | B7: 46 | C7: Male | D7: Term-20 | E7: 300000 | F7: 37636 | G7: 23 | H7: =B7+G7 -> 69 | I7: =IF(C7= "Male", INDEX(Mortality_Table_Male!$B$2:$AB$97, MATCH(Policy_Data!$B7,Mortality_Table_Male!$A$2:$A$97, 0), MATCH(IF(Policy_Data!$G7 > 25, "Ult.", Policy_Data!$G7 ), Mortality_Table_Male!$B$1:$AB$1, 0)), INDEX(Mortality_Table_Female!$B$2:$AB$97, MATCH(Policy_Data!$B7,Mortality_Table_Female!$A$2:$A$97, 0), MATCH(IF(Policy_Data!$G7 > 25, "Ult.", Policy_Data!$G7 ), Mortality_Table_Female!$B$1:$AB$1, 0))) -> 0.01405 | J7: =INDEX(Lapse_Assumptions!$A$2:$C$31,MATCH(Policy_Data!$G7, Lapse_Assumptions!$A$2:$A$31, 0), 2) -> 0.03
A8: POL1007 | B8: 47 | C8: Female | D8: Whole Life | E8: 100000 | F8: 44576 | G8: 4 | H8: =B8+G8 -> 51 | I8: =IF(C8= "Male", INDEX(Mortality_Table_Male!$B$2:$AB$97, MATCH(Policy_Data!$B8,Mortality_Table_Male!$A$2:$A$97, 0), MATCH(IF(Policy_Data!$G8 > 25, "Ult.", Policy_Data!$G8 ), Mortality_Table_Male!$B$1:$AB$1, 0)), INDEX(Mortality_Table_Female!$B$2:$AB$97, MATCH(Policy_Data!$B8,Mortality_Table_Female!$A$2:$A$97, 0), MATCH(IF(Policy_Data!$G8 > 25, "Ult.", Policy_Data!$G8 ), Mortality_Table_Female!$B$1:$AB$1, 0))) -> 0.00115 | J8: =INDEX(Lapse_Assumptions!$A$2:$C$31,MATCH(Policy_Data!$G8, Lapse_Assumptions!$A$2:$A$31, 0), 2) -> 0.06
A9: POL1008 | B9: 59 | C9: Male | D9: Whole Life | E9: 100000 | F9: 44941 | G9: 3 | H9: =B9+G9 -> 62 | I9: =IF(C9= "Male", INDEX(Mortality_Table_Male!$B$2:$AB$97, MATCH(Policy_Data!$B9,Mortality_Table_Male!$A$2:$A$97, 0), MATCH(IF(Policy_Data!$G9 > 25, "Ult.", Policy_Data!$G9 ), Mortality_Table_Male!$B$1:$AB$1, 0)), INDEX(Mortality_Table_Female!$B$2:$AB$97, MATCH(Policy_Data!$B9,Mortality_Table_Female!$A$2:$A$97, 0), MATCH(IF(Policy_Data!$G9 > 25, "Ult.", Policy_Data!$G9 ), Mortality_Table_Female!$B$1:$AB$1, 0))) -> 0.00438 | J9: =INDEX(Lapse_Assumptions!$A$2:$C$31,MATCH(Policy_Data!$G9, Lapse_Assumptions!$A$2:$A$31, 0), 2) -> 0.07
A10: POL1009 | B10: 43 | C10: Female | D10: Term-20 | E10: 100000 | F10: 36175 | G10: 27 | H10: =B10+G10 -> 70 | I10: =IF(C10= "Male", INDEX(Mortality_Table_Male!$B$2:$AB$97, MATCH(Policy_Data!$B10,Mortality_Table_Male!$A$2:$A$97, 0), MATCH(IF(Policy_Data!$G10 > 25, "Ult.", Policy_Data!$G10 ), Mortality_Table_Male!$B$1:$AB$1, 0)), INDEX(Mortality_Table_Female!$B$2:$AB$97, MATCH(Policy_Data!$B10,Mortality_Table_Female!$A$2:$A$97, 0), MATCH(IF(Policy_Data!$G10 > 25, "Ult.", Policy_Data!$G10 ), Mortality_Table_Female!$B$1:$AB$1, 0))) -> 0.01141 | J10: =INDEX(Lapse_Assumptions!$A$2:$C$31,MATCH(Policy_Data!$G10, Lapse_Assumptions!$A$2:$A$31, 0), 2) -> 0.03
A11: POL1010 | B11: 39 | C11: Female | D11: Term-20 | E11: 150000 | F11: 37636 | G11: 23 | H11: =B11+G11 -> 62 | I11: =IF(C11= "Male", INDEX(Mortality_Table_Male!$B$2:$AB$97, MATCH(Policy_Data!$B11,Mortality_Table_Male!$A$2:$A$97, 0), MATCH(IF(Policy_Data!$G11 > 25, "Ult.", Policy_Data!$G11 ), Mortality_Table_Male!$B$1:$AB$1, 0)), INDEX(Mortality_Table_Female!$B$2:$AB$97, MATCH(Policy_Data!$B11,Mortality_Table_Female!$A$2:$A$97, 0), MATCH(IF(Policy_Data!$G11 > 25, "Ult.", Policy_Data!$G11 ), Mortality_Table_Female!$B$1:$AB$1, 0))) -> 0.00546 | J11: =INDEX(Lapse_Assumptions!$A$2:$C$31,MATCH(Policy_Data!$G11, Lapse_Assumptions!$A$2:$A$31, 0), 2) -> 0.03
A12: POL1011 | B12: 49 | C12: Female | D12: Whole Life | E12: 250000 | F12: 39462 | G12: 18 | H12: =B12+G12 -> 67 | I12: =IF(C12= "Male", INDEX(Mortality_Table_Male!$B$2:$AB$97, MATCH(Policy_Data!$B12,Mortality_Table_Male!$A$2:$A$97, 0), MATCH(IF(Policy_Data!$G12 > 25, "Ult.", Policy_Data!$G12 ), Mortality_Table_Male!$B$1:$AB$1, 0)), INDEX(Mortality_Table_Female!$B$2:$AB$97, MATCH(Policy_Data!$B12,Mortality_Table_Female!$A$2:$A$97, 0), MATCH(IF(Policy_Data!$G12 > 25, "Ult.", Policy_Data!$G12 ), Mortality_Table_Female!$B$1:$AB$1, 0))) -> 0.00895 | J12: =INDEX(Lapse_Assumptions!$A$2:$C$31,MATCH(Policy_Data!$G12, Lapse_Assumptions!$A$2:$A$31, 0), 2) -> 0.03
A13: POL1012 | B13: 48 | C13: Female | D13: Term-20 | E13: 250000 | F13: 37636 | G13: 23 | H13: =B13+G13 -> 71 | I13: =IF(C13= "Male", INDEX(Mortality_Table_Male!$B$2:$AB$97, MATCH(Policy_Data!$B13,Mortality_Table_Male!$A$2:$A$97, 0), MATCH(IF(Policy_Data!$G13 > 25, "Ult.", Policy_Data!$G13 ), Mortality_Table_Male!$B$1:$AB$1, 0)), INDEX(Mortality_Table_Female!$B$2:$AB$97, MATCH(Policy_Data!$B13,Mortality_Table_Female!$A$2:$A$97, 0), MATCH(IF(Policy_Data!$G13 > 25, "Ult.", Policy_Data!$G13 ), Mortality_Table_Female!$B$1:$AB$1, 0))) -> 0.01404 | J13: =INDEX(Lapse_Assumptions!$A$2:$C$31,MATCH(Policy_Data!$G13, Lapse_Assumptions!$A$2:$A$31, 0), 2) -> 0.03
... A20: POL1019 | B20: 48 | C20: Male | D20: Term-20 | E20: 500000 | F20: 44576 | G20: 4 | H20: =B20+G20 -> 52 | I20: =IF(C20= "Male", INDEX(Mortality_Table_Male!$B$2:$AB$97, MATCH(Policy_Data!$B20,Mortality_Table_Male!$A$2:$A$97, 0), MATCH(IF(Policy_Data!$G20 > 25, "Ult.", Policy_Data!$G20 ), Mortality_Table_Male!$B$1:$AB$1, 0)), INDEX(Mortality_Table_Female!$B$2:$AB$97, MATCH(Policy_Data!$B20,Mortality_Table_Female!$A$2:$A$97, 0), MATCH(IF(Policy_Data!$G20 > 25, "Ult.", Policy_Data!$G20 ), Mortality_Table_Female!$B$1:$AB$1, 0))) -> 0.00175 | J20: =INDEX(Lapse_Assumptions!$A$2:$C$31,MATCH(Policy_Data!$G20, Lapse_Assumptions!$A$2:$A$31, 0), 2) -> 0.06

Sheet Experience Study
A1: Policy ID | B1: Policy Year | C1: Age at Start of Year | D1: Gender | E1: Expected qx | F1: Actual Death
A2: POL1015 | B2: 1 | C2: =VLOOKUP('Experience Study'!A2,Policy_Data!$A$2:$J$20, 2) -> 27 | D2: =VLOOKUP('Experience Study'!A2,Policy_Data!$A$2:$J$20, 3) -> Female | E2: {=INDEX(Mortality_Table_Female!$B$2:$AB$97, MATCH('Experience Study'!$C$2,Mortality_Table_Female!$A$2:$A$97, 0 ), IF(B2>25,26, MATCH('Experience Study'!B2, Mortality_Table_Female!$B$1:$AB$1, 0)))} -> 0.00012
A3: POL1015 | B3: =B2+1 -> 2 | C3: =C2+1 -> 28 | D3: Female | E3: {=INDEX(Mortality_Table_Female!$B$2:$AB$97, MATCH('Experience Study'!$C$2,Mortality_Table_Female!$A$2:$A$97, 0 ), IF(B3>25,26, MATCH('Experience Study'!B3, Mortality_Table_Female!$B$1:$AB$1, 0)))} -> 0.00017
A4: POL1015 | B4: =B3+1 -> 3 | C4: =C3+1 -> 29 | D4: Female | E4: {=INDEX(Mortality_Table_Female!$B$2:$AB$97, MATCH('Experience Study'!$C$2,Mortality_Table_Female!$A$2:$A$97, 0 ), IF(B4>25,26, MATCH('Experience Study'!B4, Mortality_Table_Female!$B$1:$AB$1, 0)))} -> 0.0002
A5: POL1015 | B5: =B4+1 -> 4 | C5: =C4+1 -> 30 | D5: Female | E5: {=INDEX(Mortality_Table_Female!$B$2:$AB$97, MATCH('Experience Study'!$C$2,Mortality_Table_Female!$A$2:$A$97, 0 ), IF(B5>25,26, MATCH('Experience Study'!B5, Mortality_Table_Female!$B$1:$AB$1, 0)))} -> 0.00022
A6: POL1015 | B6: =B5+1 -> 5 | C6: =C5+1 -> 31 | D6: Female | E6: {=INDEX(Mortality_Table_Female!$B$2:$AB$97, MATCH('Experience Study'!$C$2,Mortality_Table_Female!$A$2:$A$97, 0 ), IF(B6>25,26, MATCH('Experience Study'!B6, Mortality_Table_Female!$B$1:$AB$1, 0)))} -> 0.00026
A7: POL1015 | B7: =B6+1 -> 6 | C7: =C6+1 -> 32 | D7: Female | E7: {=INDEX(Mortality_Table_Female!$B$2:$AB$97, MATCH('Experience Study'!$C$2,Mortality_Table_Female!$A$2:$A$97, 0 ), IF(B7>25,26, MATCH('Experience Study'!B7, Mortality_Table_Female!$B$1:$AB$1, 0)))} -> 0.00029
A8: POL1015 | B8: =B7+1 -> 7 | C8: =C7+1 -> 33 | D8: Female | E8: {=INDEX(Mortality_Table_Female!$B$2:$AB$97, MATCH('Experience Study'!$C$2,Mortality_Table_Female!$A$2:$A$97, 0 ), IF(B8>25,26, MATCH('Experience Study'!B8, Mortality_Table_Female!$B$1:$AB$1, 0)))} -> 0.00034
A9: POL1015 | B9: =B8+1 -> 8 | C9: =C8+1 -> 34 | D9: Female | E9: {=INDEX(Mortality_Table_Female!$B$2:$AB$97, MATCH('Experience Study'!$C$2,Mortality_Table_Female!$A$2:$A$97, 0 ), IF(B9>25,26, MATCH('Experience Study'!B9, Mortality_Table_Female!$B$1:$AB$1, 0)))} -> 0.0004
A10: POL1015 | B10: =B9+1 -> 9 | C10: =C9+1 -> 35 | D10: Female | E10: {=INDEX(Mortality_Table_Female!$B$2:$AB$97, MATCH('Experience Study'!$C$2,Mortality_Table_Female!$A$2:$A$97, 0 ), IF(B10>25,26, MATCH('Experience Study'!B10, Mortality_Table_Female!$B$1:$AB$1, 0)))} -> 0.00047
A11: POL1015 | B11: =B10+1 -> 10 | C11: =C10+1 -> 36 | D11: Female | E11: {=INDEX(Mortality_Table_Female!$B$2:$AB$97, MATCH('Experience Study'!$C$2,Mortality_Table_Female!$A$2:$A$97, 0 ), IF(B11>25,26, MATCH('Experience Study'!B11, Mortality_Table_Female!$B$1:$AB$1, 0)))} -> 0.00054
A12: POL1015 | B12: =B11+1 -> 11 | C12: =C11+1 -> 37 | D12: Female | E12: {=INDEX(Mortality_Table_Female!$B$2:$AB$97, MATCH('Experience Study'!$C$2,Mortality_Table_Female!$A$2:$A$97, 0 ), IF(B12>25,26, MATCH('Experience Study'!B12, Mortality_Table_Female!$B$1:$AB$1, 0)))} -> 0.00062
A13: POL1015 | B13: =B12+1 -> 12 | C13: =C12+1 -> 38 | D13: Female | E13: {=INDEX(Mortality_Table_Female!$B$2:$AB$97, MATCH('Experience Study'!$C$2,Mortality_Table_Female!$A$2:$A$97, 0 ), IF(B13>25,26, MATCH('Experience Study'!B13, Mortality_Table_Female!$B$1:$AB$1, 0)))} -> 0.00072
A14: POL1015 | B14: =B13+1 -> 13 | C14: =C13+1 -> 39 | D14: Female | E14: {=INDEX(Mortality_Table_Female!$B$2:$AB$97, MATCH('Experience Study'!$C$2,Mortality_Table_Female!$A$2:$A$97, 0 ), IF(B14>25,26, MATCH('Experience Study'!B14, Mortality_Table_Female!$B$1:$AB$1, 0)))} -> 0.00083
... A24: POL1015 | B24: =B23+1 -> 23 | C24: =C23+1 -> 49 | D24: Female | E24: {=INDEX(Mortality_Table_Female!$B$2:$AB$97, MATCH('Experience Study'!$C$2,Mortality_Table_Female!$A$2:$A$97, 0 ), IF(B24>25,26, MATCH('Experience Study'!B24, Mortality_Table_Female!$B$1:$AB$1, 0)))} -> 0.00187
A26: POL1014 | B26: 1 | C26: =VLOOKUP('Experience Study'!A26,Policy_Data!$A$2:$J$20, 2) -> 42 | D26: =VLOOKUP('Experience Study'!A26,Policy_Data!$A$2:$J$20, 3) -> Male | E26: {=INDEX(Mortality_Table_Male!$B$2:$AB$97, MATCH('Experience Study'!$C$26,Mortality_Table_Male!$A$2:$A$97, 0 ), IF(B26>25,26, MATCH('Experience Study'!B26, Mortality_Table_Male!$B$1:$AB$1, 0)))} -> 0.00039
A27: POL1014 | B27: =B26+1 -> 2 | C27: =C26+1 -> 43 | D27: Male | E27: {=INDEX(Mortality_Table_Male!$B$2:$AB$97, MATCH('Experience Study'!$C$26,Mortality_Table_Male!$A$2:$A$97, 0 ), IF(B27>25,26, MATCH('Experience Study'!B27, Mortality_Table_Male!$B$1:$AB$1, 0)))} -> 0.00067
A28: POL1014 | B28: =B27+1 -> 3 | C28: =C27+1 -> 44 | D28: Male | E28: {=INDEX(Mortality_Table_Male!$B$2:$AB$97, MATCH('Experience Study'!$C$26,Mortality_Table_Male!$A$2:$A$97, 0 ), IF(B28>25,26, MATCH('Experience Study'!B28, Mortality_Table_Male!$B$1:$AB$1, 0)))} -> 0.00087
A29: POL1014 | B29: =B28+1 -> 4 | C29: =C28+1 -> 45 | D29: Male | E29: {=INDEX(Mortality_Table_Male!$B$2:$AB$97, MATCH('Experience Study'!$C$26,Mortality_Table_Male!$A$2:$A$97, 0 ), IF(B29>25,26, MATCH('Experience Study'!B29, Mortality_Table_Male!$B$1:$AB$1, 0)))} -> 0.00101
A30: POL1014 | B30: =B29+1 -> 5 | C30: =C29+1 -> 46 | D30: Male | E30: {=INDEX(Mortality_Table_Male!$B$2:$AB$97, MATCH('Experience Study'!$C$26,Mortality_Table_Male!$A$2:$A$97, 0 ), IF(B30>25,26, MATCH('Experience Study'!B30, Mortality_Table_Male!$B$1:$AB$1, 0)))} -> 0.00117
A31: POL1014 | B31: =B30+1 -> 6 | C31: =C30+1 -> 47 | D31: Male | E31: {=INDEX(Mortality_Table_Male!$B$2:$AB$97, MATCH('Experience Study'!$C$26,Mortality_Table_Male!$A$2:$A$97, 0 ), IF(B31>25,26, MATCH('Experience Study'!B31, Mortality_Table_Male!$B$1:$AB$1, 0)))} -> 0.00133
A32: POL1014 | B32: =B31+1 -> 7 | C32: =C31+1 -> 48 | D32: Male | E32: {=INDEX(Mortality_Table_Male!$B$2:$AB$97, MATCH('Experience Study'!$C$26,Mortality_Table_Male!$A$2:$A$97, 0 ), IF(B32>25,26, MATCH('Experience Study'!B32, Mortality_Table_Male!$B$1:$AB$1, 0)))} -> 0.00152
A33: POL1014 | B33: =B32+1 -> 8 | C33: =C32+1 -> 49 | D33: Male | E33: {=INDEX(Mortality_Table_Male!$B$2:$AB$97, MATCH('Experience Study'!$C$26,Mortality_Table_Male!$A$2:$A$97, 0 ), IF(B33>25,26, MATCH('Experience Study'!B33, Mortality_Table_Male!$B$1:$AB$1, 0)))} -> 0.00174
A34: POL1014 | B34: =B33+1 -> 9 | C34: =C33+1 -> 50 | D34: Male | E34: {=INDEX(Mortality_Table_Male!$B$2:$AB$97, MATCH('Experience Study'!$C$26,Mortality_Table_Male!$A$2:$A$97, 0 ), IF(B34>25,26, MATCH('Experience Study'!B34, Mortality_Table_Male!$B$1:$AB$1, 0)))} -> 0.002
A35: POL1014 | B35: =B34+1 -> 10 | C35: =C34+1 -> 51 | D35: Male | E35: {=INDEX(Mortality_Table_Male!$B$2:$AB$97, MATCH('Experience Study'!$C$26,Mortality_Table_Male!$A$2:$A$97, 0 ), IF(B35>25,26, MATCH('Experience Study'!B35, Mortality_Table_Male!$B$1:$AB$1, 0)))} -> 0.00228
A36: POL1014 | B36: =B35+1 -> 11 | C36: =C35+1 -> 52 | D36: Male | E36: {=INDEX(Mortality_Table_Male!$B$2:$AB$97, MATCH('Experience Study'!$C$26,Mortality_Table_Male!$A$2:$A$97, 0 ), IF(B36>25,26, MATCH('Experience Study'!B36, Mortality_Table_Male!$B$1:$AB$1, 0)))} -> 0.00254
A38: POL1017 | B38: 1 | C38: =VLOOKUP('Experience Study'!A38,Policy_Data!$A$2:$J$20, 2) -> 54 | D38: =VLOOKUP('Experience Study'!A38,Policy_Data!$A$2:$J$20, 3) -> Male | E38: {=INDEX(Mortality_Table_Male!$B$2:$AB$97, MATCH('Experience Study'!$C$38,Mortality_Table_Male!$A$2:$A$97, 0 ), IF(B38>25,26, MATCH('Experience Study'!B38, Mortality_Table_Male!$B$1:$AB$1, 0)))} -> 0.00101
A39: POL1017 | B39: =B38+1 -> 2 | C39: =C38+1 -> 55 | D39: =VLOOKUP('Experience Study'!A39,Policy_Data!$A$2:$J$20, 3) -> Male | E39: {=INDEX(Mortality_Table_Male!$B$2:$AB$97, MATCH('Experience Study'!$C$38,Mortality_Table_Male!$A$2:$A$97, 0 ), IF(B39>25,26, MATCH('Experience Study'!B39, Mortality_Table_Male!$B$1:$AB$1, 0)))} -> 0.00185
A40: POL1017 | B40: =B39+1 -> 3 | C40: =C39+1 -> 56 | D40: =VLOOKUP('Experience Study'!A40,Policy_Data!$A$2:$J$20, 3) -> Male | E40: {=INDEX(Mortality_Table_Male!$B$2:$AB$97, MATCH('Experience Study'!$C$38,Mortality_Table_Male!$A$2:$A$97, 0 ), IF(B40>25,26, MATCH('Experience Study'!B40, Mortality_Table_Male!$B$1:$AB$1, 0)))} -> 0.00272
A41: POL1017 | B41: =B40+1 -> 4 | C41: =C40+1 -> 57 | D41: =VLOOKUP('Experience Study'!A41,Policy_Data!$A$2:$J$20, 3) -> Male | E41: {=INDEX(Mortality_Table_Male!$B$2:$AB$97, MATCH('Experience Study'!$C$38,Mortality_Table_Male!$A$2:$A$97, 0 ), IF(B41>25,26, MATCH('Experience Study'!B41, Mortality_Table_Male!$B$1:$AB$1, 0)))} -> 0.00351
A42: POL1017 | B42: =B41+1 -> 5 | C42: =C41+1 -> 58 | D42: =VLOOKUP('Experience Study'!A42,Policy_Data!$A$2:$J$20, 3) -> Male | E42: {=INDEX(Mortality_Table_Male!$B$2:$AB$97, MATCH('Experience Study'!$C$38,Mortality_Table_Male!$A$2:$A$97, 0 ), IF(B42>25,26, MATCH('Experience Study'!B42, Mortality_Table_Male!$B$1:$AB$1, 0)))} -> 0.00404
A43: POL1017 | B43: =B42+1 -> 6 | C43: =C42+1 -> 59 | D43: =VLOOKUP('Experience Study'!A43,Policy_Data!$A$2:$J$20, 3) -> Male | E43: {=INDEX(Mortality_Table_Male!$B$2:$AB$97, MATCH('Experience Study'!$C$38,Mortality_Table_Male!$A$2:$A$97, 0 ), IF(B43>25,26, MATCH('Experience Study'!B43, Mortality_Table_Male!$B$1:$AB$1, 0)))} -> 0.00461
A44: POL1017 | B44: =B43+1 -> 7 | C44: =C43+1 -> 60 | D44: =VLOOKUP('Experience Study'!A44,Policy_Data!$A$2:$J$20, 3) -> Male | E44: {=INDEX(Mortality_Table_Male!$B$2:$AB$97, MATCH('Experience Study'!$C$38,Mortality_Table_Male!$A$2:$A$97, 0 ), IF(B44>25,26, MATCH('Experience Study'!B44, Mortality_Table_Male!$B$1:$AB$1, 0)))} -> 0.0053
A45: POL1017 | B45: =B44+1 -> 8 | C45: =C44+1 -> 61 | D45: =VLOOKUP('Experience Study'!A45,Policy_Data!$A$2:$J$20, 3) -> Male | E45: {=INDEX(Mortality_Table_Male!$B$2:$AB$97, MATCH('Experience Study'!$C$38,Mortality_Table_Male!$A$2:$A$97, 0 ), IF(B45>25,26, MATCH('Experience Study'!B45, Mortality_Table_Male!$B$1:$AB$1, 0)))} -> 0.00618
A46: POL1017 | B46: =B45+1 -> 9 | C46: =C45+1 -> 62 | D46: =VLOOKUP('Experience Study'!A46,Policy_Data!$A$2:$J$20, 3) -> Male | E46: {=INDEX(Mortality_Table_Male!$B$2:$AB$97, MATCH('Experience Study'!$C$38,Mortality_Table_Male!$A$2:$A$97, 0 ), IF(B46>25,26, MATCH('Experience Study'!B46, Mortality_Table_Male!$B$1:$AB$1, 0)))} -> 0.00717
A47: POL1017 | B47: =B46+1 -> 10 | C47: =C46+1 -> 63 | D47: =VLOOKUP('Experience Study'!A47,Policy_Data!$A$2:$J$20, 3) -> Male | E47: {=INDEX(Mortality_Table_Male!$B$2:$AB$97, MATCH('Experience Study'!$C$38,Mortality_Table_Male!$A$2:$A$97, 0 ), IF(B47>25,26, MATCH('Experience Study'!B47, Mortality_Table_Male!$B$1:$AB$1, 0)))} -> 0.00803
A48: POL1017 | B48: =B47+1 -> 11 | C48: =C47+1 -> 64 | D48: =VLOOKUP('Experience Study'!A48,Policy_Data!$A$2:$J$20, 3) -> Male | E48: {=INDEX(Mortality_Table_Male!$B$2:$AB$97, MATCH('Experience Study'!$C$38,Mortality_Table_Male!$A$2:$A$97, 0 ), IF(B48>25,26, MATCH('Experience Study'!B48, Mortality_Table_Male!$B$1:$AB$1, 0)))} -> 0.00887 | F48: 1
A50: POL1004 | B50: 1 | C50: =VLOOKUP('Experience Study'!A50,Policy_Data!$A$2:$J$20, 2) -> 39 | D50: =VLOOKUP('Experience Study'!A50,Policy_Data!$A$2:$J$20, 3) -> Female | E50: {=INDEX(Mortality_Table_Female!$B$2:$AB$97, MATCH('Experience Study'!$C$50,Mortality_Table_Female!$A$2:$A$97, 0 ), IF(B50>25,26, MATCH('Experience Study'!B50, Mortality_Table_Female!$B$1:$AB$1, 0)))} -> 0.00022
A51: POL1004 | B51: =B50+1 -> 2 | C51: =C50+1 -> 40 | D51: =VLOOKUP('Experience Study'!A51,Policy_Data!$A$2:$J$20, 3) -> Female | E51: {=INDEX(Mortality_Table_Female!$B$2:$AB$97, MATCH('Experience Study'!$C$50,Mortality_Table_Female!$A$2:$A$97, 0 ), IF(B51>25,26, MATCH('Experience Study'!B51, Mortality_Table_Female!$B$1:$AB$1, 0)))} -> 0.00033
A52: POL1004 | B52: =B51+1 -> 3 | C52: =C51+1 -> 41 | D52: =VLOOKUP('Experience Study'!A52,Policy_Data!$A$2:$J$20, 3) -> Female | E52: {=INDEX(Mortality_Table_Female!$B$2:$AB$97, MATCH('Experience Study'!$C$50,Mortality_Table_Female!$A$2:$A$97, 0 ), IF(B52>25,26, MATCH('Experience Study'!B52, Mortality_Table_Female!$B$1:$AB$1, 0)))} -> 0.00048
...

Sheet Detail1
A1: Details for Sum of Expected Deaths - Duration Band: 0-9
A3: Policy ID | B3: Issue Age | C3: Gender | D3: Duration (Yr) | E3: Attained Age | F3: Expected qx | G3: Actual Death (0/1) | H3: Age Band | I3: Duration Band | J3: Expected Deaths
A4: SYN4954 | B4: 27 | C4: Male | D4: 2 | E4: 28 | F4: 0.00034 | G4: 0 | H4: 20-29 | I4: 0-9 | J4: 0.00034
A5: SYN4939 | B5: 25 | C5: Female | D5: 2 | E5: 26 | F5: 0.00019 | G5: 0 | H5: 20-29 | I5: 0-9 | J5: 0.00019
A6: SYN4921 | B6: 22 | C6: Male | D6: 8 | E6: 29 | F6: 0.00059 | G6: 0 | H6: 20-29 | I6: 0-9 | J6: 0.00059
A7: SYN0042 | B7: 25 | C7: Female | D7: 3 | E7: 27 | F7: 0.0002 | G7: 0 | H7: 20-29 | I7: 0-9 | J7: 0.0002
A8: SYN4920 | B8: 20 | C8: Female | D8: 8 | E8: 27 | F8: 0.00032 | G8: 0 | H8: 20-29 | I8: 0-9 | J8: 0.00032
A9: SYN0050 | B9: 20 | C9: Female | D9: 3 | E9: 22 | F9: 0.00029 | G9: 0 | H9: 20-29 | I9: 0-9 | J9: 0.00029
A10: SYN0062 | B10: 26 | C10: Female | D10: 2 | E10: 27 | F10: 0.00017 | G10: 0 | H10: 20-29 | I10: 0-9 | J10: 0.00017
A11: SYN0063 | B11: 20 | C11: Female | D11: 3 | E11: 22 | F11: 0.00029 | G11: 0 | H11: 20-29 | I11: 0-9 | J11: 0.00029
A12: SYN4877 | B12: 25 | C12: Female | D12: 1 | E12: 25 | F12: 0.00016 | G12: 0 | H12: 20-29 | I12: 0-9 | J12: 0.00016
A13: SYN4872 | B13: 22 | C13: Male | D13: 7 | E13: 28 | F13: 0.0006 | G13: 0 | H13: 20-29 | I13: 0-9 | J13: 0.0006
A14: SYN0081 | B14: 26 | C14: Female | D14: 3 | E14: 28 | F14: 0.00019 | G14: 0 | H14: 20-29 | I14: 0-9 | J14: 0.00019
A15: SYN4857 | B15: 20 | C15: Female | D15: 6 | E15: 25 | F15: 0.00032 | G15: 0 | H15: 20-29 | I15: 0-9 | J15: 0.00032
... A1536: SYN1799 | B1536: 64 | C1536: Female | D1536: 7 | E1536: 70 | F1536: 0.00825 | G1536: 0 | H1536: 70-79 | I1536: 0-9 | J1536: 0.00825

Sheet Sheet1
B3: Column Labels
B4: 0-9 | E4: 10-19 | H4: 20-29 | K4: 30-39 | N4: Total Sum of Expected Deaths | O4: Total Sum of Actual Death (0/1) | P4: Total AERatio
A5: Row Labels | B5: Sum of Expected Deaths | C5: Sum of Actual Death (0/1) | D5: AERatio | E5: Sum of Expected Deaths | F5: Sum of Actual Death (0/1) | G5: AERatio | H5: Sum of Expected Deaths | I5: Sum of Actual Death (0/1) | J5: AERatio | K5: Sum of Expected Deaths | L5: Sum of Actual Death (0/1) | M5: AERatio
A6: 20-29 | B6: 0.07357 | C6: 0 | D6: 0 | E6: 0.00218 | F6: 0 | G6: 0 | J6: #DIV/0! | M6: #DIV/0! | N6: 0.07575 | O6: 0 | P6: 0
A7: 30-39 | B7: 0.13592 | C7: 0 | D7: 0 | E7: 0.17887 | F7: 0 | G7: 0 | H7: 0.01114 | I7: 0 | J7: 0 | M7: #DIV/0! | N7: 0.32593 | O7: 0 | P7: 0
A8: 40-49 | B8: 0.3059 | C8: 0 | D8: 0 | E8: 0.4781 | F8: 0 | G8: 0 | H8: 0.43141 | I8: 0 | J8: 0 | K8: 0.00784 | L8: 0 | M8: 0 | N8: 1.22325 | O8: 0 | P8: 0
A9: 50-59 | B9: 0.71408 | C9: 0 | D9: 0 | E9: 1.10893 | F9: 0 | G9: 0 | H9: 1.14798 | I9: 0 | J9: 0 | K9: 0.10276 | L9: 0 | M9: 0 | N9: 3.07375 | O9: 0 | P9: 0
A10: 60-69 | B10: 1.76072 | C10: 2 | D10: 1.135899 | E10: 2.94353 | F10: 3 | G10: 1.0191844 | H10: 3.48106 | I10: 0 | J10: 0 | K10: 0.23362 | L10: 0 | M10: 0 | N10: 8.41893 | O10: 5 | P10: 0.5938997
